Workbook

Sheet Sheet
A1: Question_id | B1: Dimension | C1: Question_text | D1: Answer_options_1 | E1: Answer_options_2 | F1: Answer_options_3 | G1: Answertype | H1: Scoring_rule | I1: Retrieval_query | J1: Evidence_expectation | K1: Weight | L1: Score numeric | M1: Selected_option | N1: Points | O1: Weighted_points | P1: Max_points | Q1: Normalized_0_5 | R1: EU_AI_ACT | S1: NIST_AI_RMF | T1: ISO_42001 | U1: AI_TRISM
A2: 1 | B2: Data Readiness | C2: Is data available and accessible for AI initiatives? | D2: Data needed for AI initiatives is scattered across systems, difficult to locate, and often requires manual extraction or individual access requests. There is no clear ownership, catalog, or standardized way to make datasets available for reuse. | E2: Key datasets for AI initiatives can be accessed, but availability depends on specific teams, projects, or technical specialists. Some documentation or data pipelines exist, yet access is not consistently standardized across the organization and reuse remains limited. | F2: Relevant data for AI initiatives is discoverable, documented, and accessible through standardized mechanisms such as data catalogs, governed pipelines, or self-service platforms. Ownership, access controls, and data provisioning processes are clearly defined to support scalable AI development. | G2: single_choice | H2: 1->1, 2->3, 3->5 | K2: 5 | L2: =IF(M2="",0,N2) -> 0 | N2: =IF(M2="", "", IF(M2=1,1,IF(M2=2,3,IF(M2=3,5,"")))) | O2: =IF(M2="", "", N2 * IF(K2="",1,K2)) | P2: =5 * IF(K2="",1,K2) -> 25 | Q2: =IF(M2="", "", (O2 / P2) * 5) | R2: YES | S2: YES | T2: YES | U2: YES
A3: 2 | B3: Data Readiness | C3: Are fairness metrics systematically evaluated when assessing AI model performance across different groups or populations? | D3: Model performance evaluation relies solely on traditional accuracy metrics, neglecting the measurement of fairness across protected groups or sub-populations. | E3: Data scientists are aware of fairness metrics and occasionally apply them, but their use is not standardized, documented, or integrated into the formal model acceptance criteria. | F3: Standardized fairness metrics (e.g., equal opportunity, demographic parity) are systematically applied, tracked, and reported as a mandatory component of the model development and deployment process. | G3: single_choice | H3: 1->1, 2->3, 3->6 | K3: 4 | L3: =IF(M3="",0,N3) -> 0 | N3: =IF(M3="", "", IF(M3=1,1,IF(M3=2,3,IF(M3=3,5,"")))) | O3: =IF(M3="", "", N3 * IF(K3="",1,K3)) | P3: =5 * IF(K3="",1,K3) -> 20 | Q3: =IF(M3="", "", (O3 / P3) * 5) | R3: YES | S3: YES | T3: YES | U3: YES
A4: 3 | B4: Data Readiness | C4: Does data coverage span across business processes? | D4: Data coverage is fragmented and limited to a small number of operational systems or departments, meaning many business processes lack sufficient data to support meaningful AI analysis or model development. | E4: Data coverage includes several key business processes, enabling some AI use cases, but important parts of the value chain remain poorly represented or require significant manual integration across systems. | F4: Data coverage spans the majority of critical business processes, with integrated datasets providing consistent, end-to-end visibility across the value chain to support scalable and reliable AI development. If you want, I can also help you standardize all answer sets so they consistently follow the same maturity pattern (which makes your assessment much stronger and easier to score). | G4: single_choice | H4: 1->1, 2->3, 3->7 | K4: 4 | L4: =IF(M4="",0,N4) -> 0 | N4: =IF(M4="", "", IF(M4=1,1,IF(M4=2,3,IF(M4=3,5,"")))) | O4: =IF(M4="", "", N4 * IF(K4="",1,K4)) | P4: =5 * IF(K4="",1,K4) -> 20 | Q4: =IF(M4="", "", (O4 / P4) * 5) | R4: YES | S4: YES | T4: YES
A5: 4 | B5: Data Readiness | C5: Is data quality complete and accurate? | D5: This is not in place; practices are ad hoc and rely on manual workarounds in isolated teams. | E5: Data quality complete and accurate exists for some key datasets or processes, but it is inconsistent across teams and not fully documented or standardized. | F5: This is implemented enterprise-wide with clear ownership, standards, and automation where possible, enabling consistent and scalable AI use. | G5: single_choice | H5: 1->1, 2->3, 3->8 | K5: 5 | L5: =IF(M5="",0,N5) -> 0 | N5: =IF(M5="", "", IF(M5=1,1,IF(M5=2,3,IF(M5=3,5,"")))) | O5: =IF(M5="", "", N5 * IF(K5="",1,K5)) | P5: =5 * IF(K5="",1,K5) -> 25 | Q5: =IF(M5="", "", (O5 / P5) * 5) | R5: YES | S5: YES | T5: YES | U5: YES
A6: 5 | B6: Data Readiness | C6: Is data consistent across systems? | D6: This is not in place; practices are ad hoc and rely on manual workarounds in isolated teams. | E6: Data consistent across systems exists for some key datasets or processes, but it is inconsistent across teams and not fully documented or standardized. | F6: This is implemented enterprise-wide with clear ownership, standards, and automation where possible, enabling consistent and scalable AI use. | G6: single_choice | H6: 1->1, 2->3, 3->9 | K6: 5 | L6: =IF(M6="",0,N6) -> 0 | N6: =IF(M6="", "", IF(M6=1,1,IF(M6=2,3,IF(M6=3,5,"")))) | O6: =IF(M6="", "", N6 * IF(K6="",1,K6)) | P6: =5 * IF(K6="",1,K6) -> 25 | Q6: =IF(M6="", "", (O6 / P6) * 5) | R6: YES | S6: YES | T6: YES
A7: 6 | B7: Data Readiness | C7: Are AI model inputs, outputs, and decisions systematically logged to ensure traceability and auditability? | D7: Model predictions and the data used to generate them are not systematically logged, making it impossible to trace an AI decision back to its input or version. | E7: Some basic logging of model inputs and outputs is implemented in production systems, but it lacks versioning and comprehensive metadata required for a full forensic analysis. | F7: A robust, comprehensive audit trail is maintained for every AI decision, meticulously logging the model version, input features, prediction, and associated confidence scores for regulatory compliance and debugging. | G7: single_choice | H7: 1->1, 2->3, 3->10 | K7: 4 | L7: =IF(M7="",0,N7) -> 0 | N7: =IF(M7="", "", IF(M7=1,1,IF(M7=2,3,IF(M7=3,5,"")))) | O7: =IF(M7="", "", N7 * IF(K7="",1,K7)) | P7: =5 * IF(K7="",1,K7) -> 20 | Q7: =IF(M7="", "", (O7 / P7) * 5) | R7: YES | S7: YES | T7: YES | U7: YES
A8: 7 | B8: Data Readiness | C8: Is data up to date and updated frequently? | D8: Data is updated infrequently or with significant delays, meaning AI models often rely on outdated information that reduces the reliability and relevance of predictions or insights. | E8: Some datasets are updated regularly and support certain AI use cases, but refresh cycles vary across systems and processes, leading to inconsistent data timeliness. | F8: Data pipelines ensure datasets are updated consistently and at the frequency required for the use case, with automated refresh mechanisms enabling near real-time or regularly scheduled updates for AI models. | G8: single_choice | H8: 1->1, 2->3, 3->11 | K8: 4 | L8: =IF(M8="",0,N8) -> 0 | N8: =IF(M8="", "", IF(M8=1,1,IF(M8=2,3,IF(M8=3,5,"")))) | O8: =IF(M8="", "", N8 * IF(K8="",1,K8)) | P8: =5 * IF(K8="",1,K8) -> 20 | Q8: =IF(M8="", "", (O8 / P8) * 5) | R8: YES | S8: YES | T8: YES
A9: 8 | B9: Data Readiness | C9: Is there a process for cleaning and enriching raw data? | D9: Activities are largely ad‑hoc and depend on individual initiative rather than defined processes. | E9: Some processes exist but implementation varies between teams and projects. | F9: Processes are clearly defined, consistently applied, and supported by governance and tooling. | G9: single_choice | H9: 1->1, 2->3, 3->12 | K9: 4 | L9: =IF(M9="",0,N9) -> 0 | N9: =IF(M9="", "", IF(M9=1,1,IF(M9=2,3,IF(M9=3,5,"")))) | O9: =IF(M9="", "", N9 * IF(K9="",1,K9)) | P9: =5 * IF(K9="",1,K9) -> 20 | Q9: =IF(M9="", "", (O9 / P9) * 5) | R9: YES | S9: YES | T9: YES
A10: 9 | B10: Data Readiness | C10: Are metadata and data lineage tracked and documented consistently? | D10: Critical context regarding data origin, transformations, and definitions is missing or scattered, leading to confusion, distrust, and inefficient data exploration by AI teams. | E10: Basic metadata (e.g., column names, descriptions) is captured in some systems, but comprehensive, automated data lineage tracing from source to model is not yet established. | F10: Comprehensive metadata and data lineage are systematically tracked and documented using automated tools, providing complete transparency into the origin and transformation history of all data assets. | G10: single_choice | H10: 1->1, 2->3, 3->13 | K10: 3 | L10: =IF(M10="",0,N10) -> 0 | N10: =IF(M10="", "", IF(M10=1,1,IF(M10=2,3,IF(M10=3,5,"")))) | O10: =IF(M10="", "", N10 * IF(K10="",1,K10)) | P10: =5 * IF(K10="",1,K10) -> 15 | Q10: =IF(M10="", "", (O10 / P10) * 5) | R10: YES | S10: YES | T10: YES | U10: YES
A11: 10 | B11: Data Readiness | C11: Are data privacy and compliance policies applied consistently? | D11: Compliance with regulations (e.g., GDPR, HIPAA) is left to individual teams, resulting in inconsistent application of masking, encryption, and access controls across data environments. | E11: Formal privacy policies are documented, and initial masking or anonymization is applied to sensitive data in central locations, but enforcement lacks full automation and enterprise-wide reach. | F11: Robust data privacy and compliance policies are consistently and automatically enforced across all data platforms, ensuring all AI projects adhere to regulatory requirements through automated controls. | G11: single_choice | H11: 1->1, 2->3, 3->14 | K11: 5 | L11: =IF(M11="",0,N11) -> 0 | N11: =IF(M11="", "", IF(M11=1,1,IF(M11=2,3,IF(M11=3,5,"")))) | O11: =IF(M11="", "", N11 * IF(K11="",1,K11)) | P11: =5 * IF(K11="",1,K11) -> 25 | Q11: =IF(M11="", "", (O11 / P11) * 5) | R11: YES | S11: YES | T11: YES | U11: YES
A12: 11 | B12: Data Readiness | C12: Are access and permissions properly managed? | D12: Data access is either overly permissive or managed through slow, manual request processes, creating significant security risks or causing major delays for AI development teams. | E12: Role-based access controls (RBAC) are defined for production systems, but their implementation for self-service AI development and sandbox environments remains inconsistent and manual. | F12: Granular, role-based access controls and permissions are properly managed and automated through centralized tools, ensuring secure, timely access for authorized users without hindering AI development velocity. | G12: single_choice | H12: 1->1, 2->3, 3->15 | K12: 4 | L12: =IF(M12="",0,N12) -> 0 | N12: =IF(M12="", "", IF(M12=1,1,IF(M12=2,3,IF(M12=3,5,"")))) | O12: =IF(M12="", "", N12 * IF(K12="",1,K12)) | P12: =5 * IF(K12="",1,K12) -> 20 | Q12: =IF(M12="", "", (O12 / P12) * 5) | R12: YES | S12: YES | T12: YES | U12: YES
A13: 12 | B13: Data Readiness | C13: Is data volume and frequency sufficient? | D13: The quantity of historical data or the frequency of new data generation is too low to effectively train robust and generalizable deep learning or time-sensitive operational AI models. | E13: Data volume is sufficient for standard machine learning, but highly specialized or large-scale deep learning initiatives still encounter constraints on historical depth or real-time velocity. | F13: Data volume and update frequency are fully sufficient to support all planned AI initiatives, enabling the training of large-scale models and near-real-time operational deployments. | G13: single_choice | H13: 1->1, 2->3, 3->16 | K13: 3 | L13: =IF(M13="",0,N13) -> 0 | N13: =IF(M13="", "", IF(M13=1,1,IF(M13=2,3,IF(M13=3,5,"")))) | O13: =IF(M13="", "", N13 * IF(K13="",1,K13)) | P13: =5 * IF(K13="",1,K13) -> 15 | Q13: =IF(M13="", "", (O13 / P13) * 5) | R13: YES | S13: YES | T13: YES
A14: 13 | B14: Data Readiness | C14: Is there adequate data retention history? | D14: Historical data is aggressively purged or archived, meaning models cannot be trained on sufficient long-term data to capture seasonality, trends, or rare events accurately. | E14: A formal data retention policy is drafted, but enforcement is inconsistent, and historical data for several key systems is below the desired period required for robust time-series modeling. | F14: Adequate data retention policies are strictly followed, ensuring sufficient historical data depth is available for robust time-series analysis, trend modeling, and long-term model monitoring. | G14: single_choice | H14: 1->1, 2->3, 3->17 | K14: 3 | L14: =IF(M14="",0,N14) -> 0 | N14: =IF(M14="", "", IF(M14=1,1,IF(M14=2,3,IF(M14=3,5,"")))) | O14: =IF(M14="", "", N14 * IF(K14="",1,K14)) | P14: =5 * IF(K14="",1,K14) -> 15 | Q14: =IF(M14="", "", (O14 / P14) * 5) | R14: YES | S14: YES | T14: YES | U14: YES
A15: 14 | B15: Data Readiness | C15: Is there noise and redundancy in the data? | D15: Data contains significant noise, duplicates, and irrelevant features that require immense pre-processing effort and actively impede AI model performance and stability. | E15: Some data quality issues are identified; basic deduplication and standard cleaning processes are being implemented as part of the initial data engineering pipelines. | F15: Data is regularly cleaned and validated; noise and redundancy are systematically identified and removed through automated feature engineering and quality control processes. | G15: single_choice | H15: 1->1, 2->3, 3->18 | K15: 3 | L15: =IF(M15="",0,N15) -> 0 | N15: =IF(M15="", "", IF(M15=1,1,IF(M15=2,3,IF(M15=3,5,"")))) | O15: =IF(M15="", "", N15 * IF(K15="",1,K15)) | P15: =5 * IF(K15="",1,K15) -> 15 | Q15: =IF(M15="", "", (O15 / P15) * 5) | R15: YES | S15: YES | T15: YES
A16: 15 | B16: Data Readiness | C16: Is the data biased or representative? | D16: The training data contains significant systemic biases (e.g., underrepresentation of specific customer segments), leading to AI models that will exhibit unfair or discriminatory outcomes. | E16: Initial data assessments have highlighted potential biases in certain features or historical outcomes, and mitigation strategies like re-sampling are being explored and piloted. | F16: The data is systematically assessed for bias and is actively managed to be statistically representative of the target population and use case, ensuring fair and equitable model outcomes. | G16: single_choice | H16: 1->1, 2->3, 3->19 | K16: 5 | L16: =IF(M16="",0,N16) -> 0 | N16: =IF(M16="", "", IF(M16=1,1,IF(M16=2,3,IF(M16=3,5,"")))) | O16: =IF(M16="", "", N16 * IF(K16="",1,K16)) | P16: =5 * IF(K16="",1,K16) -> 25 | Q16: =IF(M16="", "", (O16 / P16) * 5) | R16: YES | S16: YES | T16: YES | U16: YES
A17: 16 | B17: Data Readiness | C17: Is label quality sufficient for supervised learning? | D17: Labels for supervised learning are not available highly inconsistent, noisy, or incorrectly applied, significantly limiting the model's ability to achieve high accuracy and generalization. | E17: Labeling is primarily done by subject matter experts with some basic spot-checking, but formal quality control and inter-rater agreement processes are not yet standard practice. | F17: A high standard of label quality is maintained through rigorous review, multiple expert annotations, and formal quality control processes (e.g., inter-rater reliability) for all training data sets. | G17: single_choice | H17: 1->1, 2->3, 3->20 | K17: 4 | L17: =IF(M17="",0,N17) -> 0 | N17: =IF(M17="", "", IF(M17=1,1,IF(M17=2,3,IF(M17=3,5,"")))) | O17: =IF(M17="", "", N17 * IF(K17="",1,K17)) | P17: =5 * IF(K17="",1,K17) -> 20 | Q17: =IF(M17="", "", (O17 / P17) * 5) | S17: YES | T17: YES | U17: YES
A18: 17 | B18: Data Readiness | C18: Is there feature richness and granularity in the data? | D18: The available data is highly aggregated or lacks detailed attributes (features), preventing the AI models from capturing complex patterns or generating highly precise predictions. | E18: Core transactional data is available at a granular level, but enrichment with external or unstructured data sources to create rich features is performed only on select, high-priority projects. | F18: The data exhibits high feature richness and granularity, incorporating both core and enriched features that enable models to capture subtle, complex patterns for superior predictive power. | G18: single_choice | H18: 1->1, 2->3, 3->21 | K18: 3 | L18: =IF(M18="",0,N18) -> 0 | N18: =IF(M18="", "", IF(M18=1,1,IF(M18=2,3,IF(M18=3,5,"")))) | O18: =IF(M18="", "", N18 * IF(K18="",1,K18)) | P18: =5 * IF(K18="",1,K18) -> 15 | Q18: =IF(M18="", "", (O18 / P18) * 5) | R18: YES | S18: YES | T18: YES
A19: 18 | B19: Data Readiness | C19: Is there historical consistency in the data? | D19: Data schema, definitions, or collection methods have changed frequently over time, making older historical data incompatible or unreliable for training long-term AI models. | E19: Data conversion and harmonization are manually performed for large historical datasets when required, but there is no automated system to enforce schema consistency across time. | F19: Historical consistency is maintained through robust data versioning, schema evolution management, and standardized data collection protocols, ensuring all historical data is reliable and usable for training. | G19: single_choice | H19: 1->1, 2->3, 3->22 | K19: 3 | L19: =IF(M19="",0,N19) -> 0 | N19: =IF(M19="", "", IF(M19=1,1,IF(M19=2,3,IF(M19=3,5,"")))) | O19: =IF(M19="", "", N19 * IF(K19="",1,K19)) | P19: =5 * IF(K19="",1,K19) -> 15 | Q19: =IF(M19="", "", (O19 / P19) * 5) | R19: YES | S19: YES | T19: YES
A20: 19 | B20: Data Readiness | C20: Does the organization have data integration capability? | D20: The organization relies on point-to-point integrations and manual data transfers, making it difficult and slow to combine data from disparate sources into unified AI training datasets. | E20: An enterprise data integration tool is being implemented, and initial APIs are being developed for key systems, but full, centralized data orchestration capabilities are not yet mature. | F20: A robust, centralized data integration capability (e.g., automated ETL/ELT pipelines, service bus) is fully in place, enabling fast and reliable data orchestration for all AI projects. | G20: single_choice | H20: 1->1, 2->3, 3->23 | K20: 4 | L20: =IF(M20="",0,N20) -> 0 | N20: =IF(M20="", "", IF(M20=1,1,IF(M20=2,3,IF(M20=3,5,"")))) | O20: =IF(M20="", "", N20 * IF(K20="",1,K20)) | P20: =5 * IF(K20="",1,K20) -> 20 | Q20: =IF(M20="", "", (O20 / P20) * 5) | R20: YES | S20: YES | T20: YES
A21: 20 | B21: Data Readiness | C21: Are training, validation, and test datasets clearly separated and documented? | D21: Datasets are reused without clear separation, making evaluation unreliable. | E21: Basic separation exists but documentation is incomplete or inconsistently applied. | F21: Datasets are systematically separated, versioned, and documented to ensure reliable evaluation and reproducibility. | G21: single_choice | H21: 1->1, 2->3, 3->24 | K21: 4 | L21: =IF(M21="",0,N21) -> 0 | N21: =IF(M21="", "", IF(M21=1,1,IF(M21=2,3,IF(M21=3,5,"")))) | O21: =IF(M21="", "", N21 * IF(K21="",1,K21)) | P21: =5 * IF(K21="",1,K21) -> 20 | Q21: =IF(M21="", "", (O21 / P21) * 5) | R21: YES | S21: YES | T21: YES
A22: 21 | B22: Data Readiness | C22: Is dataset versioning implemented to reproduce model results? | D22: No dataset versioning; historical training data cannot be reconstructed. | E22: Partial versioning exists but is manual or limited to critical projects. | F22: Automated dataset versioning allows full reproducibility of training, evaluation, and deployment. | G22: single_choice | H22: 1->1, 2->3, 3->25 | K22: 3 | L22: =IF(M22="",0,N22) -> 0 | N22: =IF(M22="", "", IF(M22=1,1,IF(M22=2,3,IF(M22=3,5,"")))) | O22: =IF(M22="", "", N22 * IF(K22="",1,K22)) | P22: =5 * IF(K22="",1,K22) -> 15 | Q22: =IF(M22="", "", (O22 / P22) * 5) | R22: YES | S22: YES | T22: YES | U22: YES
A23: 22 | B23: Data Readiness | C23: Is data documentation sufficient to understand dataset origin, purpose, and limitations? | D23: Dataset origin and limitations are largely undocumented. | E23: Some documentation exists but is inconsistent across datasets. | F23: Standardized dataset documentation describes origin, purpose, bias risks, and limitations. | G23: single_choice | H23: 1->1, 2->3, 3->26 | K23: 3 | L23: =IF(M23="",0,N23) -> 0 | N23: =IF(M23="", "", IF(M23=1,1,IF(M23=2,3,IF(M23=3,5,"")))) | O23: =IF(M23="", "", N23 * IF(K23="",1,K23)) | P23: =5 * IF(K23="",1,K23) -> 15 | Q23: =IF(M23="", "", (O23 / P23) * 5) | R23: YES | S23: YES | T23: YES | U23: YES
A24: 23 | B24: Data Readiness | C24: Are evaluation datasets representative of real-world deployment conditions? | D24: Evaluation data differs significantly from real-world usage scenarios. | E24: Some effort is made to approximate real conditions but gaps remain. | F24: Evaluation datasets reflect real-world distributions, edge cases, and risk scenarios. | G24: single_choice | H24: 1->1, 2->3, 3->27 | K24: 4 | L24: =IF(M24="",0,N24) -> 0 | N24: =IF(M24="", "", IF(M24=1,1,IF(M24=2,3,IF(M24=3,5,"")))) | O24: =IF(M24="", "", N24 * IF(K24="",1,K24)) | P24: =5 * IF(K24="",1,K24) -> 20 | Q24: =IF(M24="", "", (O24 / P24) * 5) | R24: YES | S24: YES | T24: YES | U24: YES
A25: 24 | B25: Data Readiness | C25: Is feedback data captured to improve models after deployment? | D25: No structured feedback data is captured. | E25: Feedback is collected sporadically or manually. | F25: Systematic feedback loops capture outcomes, errors, and user signals for continuous improvement. | G25: single_choice | H25: 1->1, 2->3, 3->28 | K25: 4 | L25: =IF(M25="",0,N25) -> 0 | N25: =IF(M25="", "", IF(M25=1,1,IF(M25=2,3,IF(M25=3,5,"")))) | O25: =IF(M25="", "", N25 * IF(K25="",1,K25)) | P25: =5 * IF(K25="",1,K25) -> 20 | Q25: =IF(M25="", "", (O25 / P25) * 5) | R25: YES | S25: YES | T25: YES | U25: YES
A26: 25 | B26: Data Readiness | C26: Are edge cases and rare scenarios included in datasets? | D26: Edge cases are largely missing or discovered only after failures. | E26: Some edge cases are included but not systematically identified. | F26: Edge cases are proactively identified, curated, and included in datasets. | G26: single_choice | H26: 1->1, 2->3, 3->29 | K26: 2 | L26: =IF(M26="",0,N26) -> 0 | N26: =IF(M26="", "", IF(M26=1,1,IF(M26=2,3,IF(M26=3,5,"")))) | O26: =IF(M26="", "", N26 * IF(K26="",1,K26)) | P26: =5 * IF(K26="",1,K26) -> 10 | Q26: =IF(M26="", "", (O26 / P26) * 5) | R26: YES | S26: YES | T26: YES | U26: YES
A27: 26 | B27: Data Readiness | C27: Is data prepared to support explainability and audit requirements? | D27: Data structure limits explainability and traceability. | E27: Some features support explanation but coverage is incomplete. | F27: Data is structured to enable feature attribution, explainability, and audit. | G27: single_choice | H27: 1->1, 2->3, 3->30 | K27: 4 | L27: =IF(M27="",0,N27) -> 0 | N27: =IF(M27="", "", IF(M27=1,1,IF(M27=2,3,IF(M27=3,5,"")))) | O27: =IF(M27="", "", N27 * IF(K27="",1,K27)) | P27: =5 * IF(K27="",1,K27) -> 20 | Q27: =IF(M27="", "", (O27 / P27) * 5) | R27: YES | S27: YES | T27: YES | U27: YES
A28: 27 | B28: Data Readiness | C28: Is feature engineering standardized and reusable across projects? | D28: Feature creation is ad-hoc and project specific. | E28: Some reusable features exist but are not centrally managed. | F28: A standardized feature framework enables reuse and controlled evolution. | G28: single_choice | H28: 1->1, 2->3, 3->31 | K28: 3 | L28: =IF(M28="",0,N28) -> 0 | N28: =IF(M28="", "", IF(M28=1,1,IF(M28=2,3,IF(M28=3,5,"")))) | O28: =IF(M28="", "", N28 * IF(K28="",1,K28)) | P28: =5 * IF(K28="",1,K28) -> 15 | Q28: =IF(M28="", "", (O28 / P28) * 5) | S28: YES | T28: YES
A29: 28 | B29: Data Readiness | C29: Is data quality monitored automatically in pipelines? | D29: Data quality checks are manual or reactive. | E29: Basic automated checks exist for selected datasets. | F29: Automated monitoring detects anomalies, schema changes, and drift. | G29: single_choice | H29: 1->1, 2->3, 3->32 | K29: 4 | L29: =IF(M29="",0,N29) -> 0 | N29: =IF(M29="", "", IF(M29=1,1,IF(M29=2,3,IF(M29=3,5,"")))) | O29: =IF(M29="", "", N29 * IF(K29="",1,K29)) | P29: =5 * IF(K29="",1,K29) -> 20 | Q29: =IF(M29="", "", (O29 / P29) * 5) | R29: YES | S29: YES | T29: YES | U29: YES
A30: 29 | B30: Data Readiness | C30: Is data readiness validated before model development starts? | D30: Model work begins without formal readiness validation. | E30: Readiness is assessed informally or inconsistently. | F30: A formal data readiness checklist gates model development. | G30: single_choice | H30: 1->1, 2->3, 3->33 | K30: 4 | L30: =IF(M30="",0,N30) -> 0 | N30: =IF(M30="", "", IF(M30=1,1,IF(M30=2,3,IF(M30=3,5,"")))) | O30: =IF(M30="", "", N30 * IF(K30="",1,K30)) | P30: =5 * IF(K30="",1,K30) -> 20 | Q30: =IF(M30="", "", (O30 / P30) * 5) | R30: YES | S30: YES | T30: YES | U30: YES
A31: 30 | B31: Data Readiness | C31: Is external data evaluated for reliability and suitability before use? | D31: External data is used without structured validation. | E31: Basic validation is performed but not standardized. | F31: External data undergoes systematic evaluation for quality, bias, legal use, and relevance. | G31: single_choice | H31: 1->1, 2->3, 3->34 | K31: 2 | L31: =IF(M31="",0,N31) -> 0 | N31: =IF(M31="", "", IF(M31=1,1,IF(M31=2,3,IF(M31=3,5,"")))) | O31: =IF(M31="", "", N31 * IF(K31="",1,K31)) | P31: =5 * IF(K31="",1,K31) -> 10 | Q31: =IF(M31="", "", (O31 / P31) * 5) | R31: YES | S31: YES | T31: YES | U31: YES
A32: 31 | B32: Data Readiness | C32: Is synthetic or augmented data used in a controlled way? | D32: Synthetic data usage is uncontrolled or undocumented. | E32: Synthetic data is used but governance and validation are limited. | F32: Synthetic data generation and validation follow defined standards. | G32: single_choice | H32: 1->1, 2->3, 3->35 | K32: 2 | L32: =IF(M32="",0,N32) -> 0 | N32: =IF(M32="", "", IF(M32=1,1,IF(M32=2,3,IF(M32=3,5,"")))) | O32: =IF(M32="", "", N32 * IF(K32="",1,K32)) | P32: =5 * IF(K32="",1,K32) -> 10 | Q32: =IF(M32="", "", (O32 / P32) * 5) | R32: YES | S32: YES | T32: YES | U32: YES
A33: 32 | B33: Data Readiness | C33: Is dataset coverage sufficient across time, geography, and user groups? | D33: Data coverage gaps are unknown or significant. | E33: Some coverage analysis exists but is incomplete. | F33: Systematic coverage analysis ensures inclusion across segments and time periods. | G33: single_choice | H33: 1->1, 2->3, 3->36 | K33: 3 | L33: =IF(M33="",0,N33) -> 0 | N33: =IF(M33="", "", IF(M33=1,1,IF(M33=2,3,IF(M33=3,5,"")))) | O33: =IF(M33="", "", N33 * IF(K33="",1,K33)) | P33: =5 * IF(K33="",1,K33) -> 15 | Q33: =IF(M33="", "", (O33 / P33) * 5) | R33: YES | S33: YES | T33: YES
A34: 33 | B34: Data Readiness | C34: Is annotation guidance documented to ensure labeling consistency? | D34: Labeling guidelines are absent or informal. | E34: Basic guidelines exist but are inconsistently followed. | F34: Detailed annotation protocols ensure consistent labeling. | G34: single_choice | H34: 1->1, 2->3, 3->37 | K34: 2 | L34: =IF(M34="",0,N34) -> 0 | N34: =IF(M34="", "", IF(M34=1,1,IF(M34=2,3,IF(M34=3,5,"")))) | O34: =IF(M34="", "", N34 * IF(K34="",1,K34)) | P34: =5 * IF(K34="",1,K34) -> 10 | Q34: =IF(M34="", "", (O34 / P34) * 5) | R34: YES | S34: YES | T34: YES
A35: 34 | B35: Data Readiness | C35: Is data readiness evidence captured for impact assessments and regulatory review? | D35: Evidence is not stored or cannot be retrieved. | E35: Some evidence exists but is scattered. | F35: Data readiness evidence is centrally stored and reusable for regulatory reporting. | G35: single_choice | H35: 1->1, 2->3, 3->38 | K35: 3 | L35: =IF(M35="",0,N35) -> 0 | N35: =IF(M35="", "", IF(M35=1,1,IF(M35=2,3,IF(M35=3,5,"")))) | O35: =IF(M35="", "", N35 * IF(K35="",1,K35)) | P35: =5 * IF(K35="",1,K35) -> 15 | Q35: =IF(M35="", "", (O35 / P35) * 5) | R35: YES | S35: YES | T35: YES
A36: 35 | B36: Data Readiness | C36: Are data silos limiting the ability to create integrated AI datasets? | D36: Data is fragmented across silos with limited visibility and integration. | E36: Some integration exists but requires manual effort. | F36: Data is discoverable and can be integrated efficiently across domains. | G36: single_choice | H36: 1->1, 2->3, 3->39 | K36: 4 | L36: =IF(M36="",0,N36) -> 0 | N36: =IF(M36="", "", IF(M36=1,1,IF(M36=2,3,IF(M36=3,5,"")))) | O36: =IF(M36="", "", N36 * IF(K36="",1,K36)) | P36: =5 * IF(K36="",1,K36) -> 20 | Q36: =IF(M36="", "", (O36 / P36) * 5) | S36: YES | T36: YES
A37: 36 | B37: Data Readiness | C37: Is data discoverability sufficient to identify relevant datasets for AI initiatives? | D37: This is handled reactively with no standard process; issues are resolved ad hoc and lessons are not captured. | E37: This is handled through basic processes for critical systems, but practices are not consistently applied or measured. | F37: This is managed through standardized operational processes, metrics, and continuous improvement, integrated into day-to-day delivery. | G37: single_choice | H37: 1->1, 2->3, 3->40 | K37: 3 | L37: =IF(M37="",0,N37) -> 0 | N37: =IF(M37="", "", IF(M37=1,1,IF(M37=2,3,IF(M37=3,5,"")))) | O37: =IF(M37="", "", N37 * IF(K37="",1,K37)) | P37: =5 * IF(K37="",1,K37) -> 15 | Q37: =IF(M37="", "", (O37 / P37) * 5) | R37: YES | S37: YES | T37: YES
A38: 37 | B38: Data Readiness | C38: Can datasets be reliably reconstructed from storage systems? | D38: Training datasets cannot be reliably recreated. | E38: Reconstruction is possible but manual or incomplete. | F38: Datasets can be reproducibly rebuilt using automated pipelines and lineage. | G38: single_choice | H38: 1->1, 2->3, 3->41 | K38: 2 | L38: =IF(M38="",0,N38) -> 0 | N38: =IF(M38="", "", IF(M38=1,1,IF(M38=2,3,IF(M38=3,5,"")))) | O38: =IF(M38="", "", N38 * IF(K38="",1,K38)) | P38: =5 * IF(K38="",1,K38) -> 10 | Q38: =IF(M38="", "", (O38 / P38) * 5) | R38: YES | S38: YES | T38: YES | U38: YES
A39: 38 | B39: Operations, Culture & Delivery | C39: Are frontline users involved in designing AI-enabled workflows? | D39: AI is largely disconnected from day-to-day operations; pilots do not change how work gets done. | E39: AI is used in a few workflows, but adoption is uneven and often dependent on local champions. | F39: AI is embedded in key workflows with clear ownership, training, and performance monitoring; adoption is managed like a product. | G39: single_choice | H39: 1->1, 2->3, 3->42 | K39: 3 | L39: =IF(M39="",0,N39) -> 0 | N39: =IF(M39="", "", IF(M39=1,1,IF(M39=2,3,IF(M39=3,5,"")))) | O39: =IF(M39="", "", N39 * IF(K39="",1,K39)) | P39: =5 * IF(K39="",1,K39) -> 15 | Q39: =IF(M39="", "", (O39 / P39) * 5)
A40: 39 | B40: Operations, Culture & Delivery | C40: Is AI used to increase scalability and throughput of operations? | D40: AI is largely disconnected from day-to-day operations; pilots do not change how work gets done. | E40: AI is used in a few workflows, but adoption is uneven and often dependent on local champions. | F40: AI is embedded in key workflows with clear ownership, training, and performance monitoring; adoption is managed like a product. | G40: single_choice | H40: 1->1, 2->3, 3->43 | K40: 3 | L40: =IF(M40="",0,N40) -> 0 | N40: =IF(M40="", "", IF(M40=1,1,IF(M40=2,3,IF(M40=3,5,"")))) | O40: =IF(M40="", "", N40 * IF(K40="",1,K40)) | P40: =5 * IF(K40="",1,K40) -> 15 | Q40: =IF(M40="", "", (O40 / P40) * 5)
...

Sheet Config
A1: Setting | B1: Value
A2: Tier_1_Name | B2: Emerging | D2: De organisatie erkent het potentieel van AI, maar heeft nog geen formele adoptie of strategie. Er is sprake van nieuwsgierigheid zonder praktische uitvoering.
A3: Tier_1_MinPct | B3: 0
A4: Tier_1_MaxPct | B4: 34.9
A5: Tier_2_Name | B5: Developing | D5: Er wordt op afdelingsniveau geëxperimenteerd met pilotprojecten. Teams gebruiken informeel tools zoals Jupyter notebooks voor eerste modellen.
A6: Tier_2_MinPct | B6: 35
A7: Tier_2_MaxPct | B7: 59.9
A8: Tier_3_Name | B8: Accelerating | D8: AI-modellen zijn geïntegreerd in specifieke bedrijfsprocessen met meetbare resultaten. Er is een team van machine learning engineers en een basis MLOps-infrastructuur aanwezig.
A9: Tier_3_MinPct | B9: 60
A10: Tier_3_MaxPct | B10: 79.9
A11: Tier_4_Name | B11: Leading | D11: AI is organisatiebreed ingebed en afgestemd op de bedrijfsstrategie. Er is een centrale governance, vaste budgetten en een focus op schaalbaarheid en compliance.
A12: Tier_4_MinPct | B12: 80
A13: Tier_4_MaxPct | B13: 100

Sheet Dimension_Summary
A1: Dimension | B1: Number_of_questions | C1: Sum_Weighted_points | D1: Sum_Max_points | E1: Dimension_Score_0_5 | F1: Dimension_Score_0_100
A2: Data Readiness | B2: =COUNTIF(Sheet!$B$2:$B$266,A2) -> 37 | C2: =SUMIF(Sheet!$B$2:$B$266,A2,Sheet!$O$2:$O$266) -> 0 | D2: =SUMIF(Sheet!$B$2:$B$266,A2,Sheet!$P$2:$P$266) -> 655 | E2: =IF(D2=0,"", ROUND((C2/D2)*5, 2)) -> 0 | F2: =IF(D2=0,"", ROUND((C2/D2)*100, 1)) -> 0
A3: Operations, Culture & Delivery | B3: =COUNTIF(Sheet!$B$2:$B$266,A3) -> 64 | C3: =SUMIF(Sheet!$B$2:$B$266,A3,Sheet!$O$2:$O$266) -> 0 | D3: =SUMIF(Sheet!$B$2:$B$266,A3,Sheet!$P$2:$P$266) -> 1120 | E3: =IF(D3=0,"", ROUND((C3/D3)*5, 2)) -> 0 | F3: =IF(D3=0,"", ROUND((C3/D3)*100, 1)) -> 0
A4: Risk, Compliance & Responsible AI | B4: =COUNTIF(Sheet!$B$2:$B$266,A4) -> 25 | C4: =SUMIF(Sheet!$B$2:$B$266,A4,Sheet!$O$2:$O$266) -> 0 | D4: =SUMIF(Sheet!$B$2:$B$266,A4,Sheet!$P$2:$P$266) -> 555 | E4: =IF(D4=0,"", ROUND((C4/D4)*5, 2)) -> 0 | F4: =IF(D4=0,"", ROUND((C4/D4)*100, 1)) -> 0
A5: Skills & Organizational Capability | B5: =COUNTIF(Sheet!$B$2:$B$266,A5) -> 33 | C5: =SUMIF(Sheet!$B$2:$B$266,A5,Sheet!$O$2:$O$266) -> 0 | D5: =SUMIF(Sheet!$B$2:$B$266,A5,Sheet!$P$2:$P$266) -> 585 | E5: =IF(D5=0,"", ROUND((C5/D5)*5, 2)) -> 0 | F5: =IF(D5=0,"", ROUND((C5/D5)*100, 1)) -> 0
A6: Strategic & Leadership Readiness | B6: =COUNTIF(Sheet!$B$2:$B$266,A6) -> 38 | C6: =SUMIF(Sheet!$B$2:$B$266,A6,Sheet!$O$2:$O$266) -> 0 | D6: =SUMIF(Sheet!$B$2:$B$266,A6,Sheet!$P$2:$P$266) -> 755 | E6: =IF(D6=0,"", ROUND((C6/D6)*5, 2)) -> 0 | F6: =IF(D6=0,"", ROUND((C6/D6)*100, 1)) -> 0
A7: Technology Infrastructure & Tooling | B7: =COUNTIF(Sheet!$B$2:$B$266,A7) -> 41 | C7: =SUMIF(Sheet!$B$2:$B$266,A7,Sheet!$O$2:$O$266) -> 0 | D7: =SUMIF(Sheet!$B$2:$B$266,A7,Sheet!$P$2:$P$266) -> 815 | E7: =IF(D7=0,"", ROUND((C7/D7)*5, 2)) -> 0 | F7: =IF(D7=0,"", ROUND((C7/D7)*100, 1)) -> 0
A8: Use Case Maturity & Adoption | B8: =COUNTIF(Sheet!$B$2:$B$266,A8) -> 27 | C8: =SUMIF(Sheet!$B$2:$B$266,A8,Sheet!$O$2:$O$266) -> 0 | D8: =SUMIF(Sheet!$B$2:$B$266,A8,Sheet!$P$2:$P$266) -> 540 | E8: =IF(D8=0,"", ROUND((C8/D8)*5, 2)) -> 0 | F8: =IF(D8=0,"", ROUND((C8/D8)*100, 1)) -> 0

Sheet Radar_Data
A1: Dimension | B1: Score_0_5 | C1: Score_0_100
A2: =Dimension_Summary!A2 -> Data Readiness | B2: =Dimension_Summary!E2 -> 0 | C2: =Dimension_Summary!F2 -> 0
A3: =Dimension_Summary!A3 -> Operations, Culture & Delivery | B3: =Dimension_Summary!E3 -> 0 | C3: =Dimension_Summary!F3 -> 0
A4: =Dimension_Summary!A4 -> Risk, Compliance & Responsible AI | B4: =Dimension_Summary!E4 -> 0 | C4: =Dimension_Summary!F4 -> 0
A5: =Dimension_Summary!A5 -> Skills & Organizational Capability | B5: =Dimension_Summary!E5 -> 0 | C5: =Dimension_Summary!F5 -> 0
A6: =Dimension_Summary!A6 -> Strategic & Leadership Readiness | B6: =Dimension_Summary!E6 -> 0 | C6: =Dimension_Summary!F6 -> 0
A7: =Dimension_Summary!A7 -> Technology Infrastructure & Tooling | B7: =Dimension_Summary!E7 -> 0 | C7: =Dimension_Summary!F7 -> 0
A8: =Dimension_Summary!A8 -> Use Case Maturity & Adoption | B8: =Dimension_Summary!E8 -> 0 | C8: =Dimension_Summary!F8 -> 0

Sheet Overall_Summary
A1: Metric | B1: Value
A2: Overall_Sum_Weighted_points | B2: =SUMPRODUCT((Sheet!$M$2:$M$266<>"")*IFERROR(Sheet!$O$2:$O$266,0)) -> #VALUE!
A3: Overall_Sum_Max_points | B3: =SUMPRODUCT((Sheet!$M$2:$M$266<>"")*Sheet!$P$2:$P$266) -> 0
A4: Overall_Score_0_5 | B4: =IF(B3=0,"", ROUND((B2/B3)*5, 2))
A5: Overall_Score_0_100 | B5: =IF(B3=0,"", ROUND((B2/B3)*100, 1))
A6: Maturity_Tier | B6: =IF(B5="","",IF(B5<=Config!B4,Config!B2,IF(B5<=Config!B7,Config!B5,IF(B5<=Config!B10,Config!B8,Config!B11))))
A7: Questions_answered | B7: =COUNTIF(Sheet!$M$2:$M$266,"<>"&"") -> 0
A8: Questions_total | B8: =COUNTA(Sheet!$A$2:$A$266) -> 265
A9: Completion_pct | B9: =IF(B8=0,"",ROUND(B7/B8*100,1)) -> 0

Sheet Column_Explanation
A1: Column | B1: Purpose | C1: Explanation | D1: Example
A2: Question_id | B2: Unique identifier | C2: Unique number used to reference and track each question in the assessment. | D2: 10, 11, 12
A3: Dimension | B3: Assessment domain | C3: Groups questions into domains such as Data Readiness, Governance, Technology, etc. Used for radar charts and maturity scoring per domain. | D3: Data Readiness
A4: Question_text | B4: Assessment question | C4: The actual question used to evaluate the organization’s AI maturity. | D4: Is data available and accessible for AI initiatives?
A5: Answer_options_1 | B5: Low maturity answer | C5: Represents the lowest maturity level (early stage / ad‑hoc practices). | D5: Data is scattered across systems
A6: Answer_options_2 | B6: Medium maturity answer | C6: Represents a developing or partially structured maturity level. | D6: Some datasets accessible but not standardized
A7: Answer_options_3 | B7: High maturity answer | C7: Represents the most advanced maturity level with structured processes. | D7: Data is governed and fully accessible
A8: Answer_type | B8: Question format | C8: Defines how the question should be answered (e.g. single choice). | D8: single_choice
A9: Required_docs | B9: Evidence guidance | C9: Lists documents that could demonstrate proof for the answer. | D9: AI Governance Policy
A10: Requires_evidence_boolean | B10: Evidence requirement flag | C10: Indicates whether documentation evidence is required to support the answer. | D10: TRUE / FALSE
A11: Retrieval_query | B11: AI document search query | C11: Query used by an AI system to search documentation repositories to find evidence. | D11: Find documentation describing AI governance policy
A12: Evidence_expectation | B12: Expected evidence description | C12: Defines what type of document or proof should be found. | D12: Documented AI governance framework
... A26: Maturity_Area | B26: Analysis grouping | C26: High‑level grouping used for reporting and analysis across maturity areas. | D26: Governance

Sheet Results_Dashboard
A1: AI Maturity Dashboard — Straightable Innovation & Strategy
A3: TOTAALSCORE | C3: VOLTOOIING ASSESSMENT
A4: Score (0–5) | B4: =Overall_Summary!B4 | C4: Vragen beantwoord | D4: =Overall_Summary!B7 -> 0 | E4: =Overall_Summary!B8&" vragen totaal" -> 265 vragen totaal
A5: Score (0–100%) | B5: =Overall_Summary!B5 | C5: Voltooiingspercentage | D5: =Overall_Summary!B9 -> 0
A6: Maturiteitsniveau | B6: =Overall_Summary!B6
A8: SCORES PER DIMENSIE
A9: Dimensie | B9: Score (0–5) | C9: Score (%) | D9: Max mogelijke score | E9: Maturiteitsniveau
A10: =Dimension_Summary!A2 -> Data Readiness | B10: =Dimension_Summary!E2 -> 0 | C10: =Dimension_Summary!F2 -> 0 | D10: =Dimension_Summary!D2 -> 655 | E10: =IF(Dimension_Summary!F2="","",IF(Dimension_Summary!F2<=Config!B4,Config!B2,IF(Dimension_Summary!F2<=Config!B7,Config!B5,IF(Dimension_Summary!F2<=Config!B10,Config!B8,Config!B11)))) -> Emerging
A11: =Dimension_Summary!A3 -> Operations, Culture & Delivery | B11: =Dimension_Summary!E3 -> 0 | C11: =Dimension_Summary!F3 -> 0 | D11: =Dimension_Summary!D3 -> 1120 | E11: =IF(Dimension_Summary!F3="","",IF(Dimension_Summary!F3<=Config!B4,Config!B2,IF(Dimension_Summary!F3<=Config!B7,Config!B5,IF(Dimension_Summary!F3<=Config!B10,Config!B8,Config!B11)))) -> Emerging
A12: =Dimension_Summary!A4 -> Risk, Compliance & Responsible AI | B12: =Dimension_Summary!E4 -> 0 | C12: =Dimension_Summary!F4 -> 0 | D12: =Dimension_Summary!D4 -> 555 | E12: =IF(Dimension_Summary!F4="","",IF(Dimension_Summary!F4<=Config!B4,Config!B2,IF(Dimension_Summary!F4<=Config!B7,Config!B5,IF(Dimension_Summary!F4<=Config!B10,Config!B8,Config!B11)))) -> Emerging
A13: =Dimension_Summary!A5 -> Skills & Organizational Capability | B13: =Dimension_Summary!E5 -> 0 | C13: =Dimension_Summary!F5 -> 0 | D13: =Dimension_Summary!D5 -> 585 | E13: =IF(Dimension_Summary!F5="","",IF(Dimension_Summary!F5<=Config!B4,Config!B2,IF(Dimension_Summary!F5<=Config!B7,Config!B5,IF(Dimension_Summary!F5<=Config!B10,Config!B8,Config!B11)))) -> Emerging
A14: =Dimension_Summary!A6 -> Strategic & Leadership Readiness | B14: =Dimension_Summary!E6 -> 0 | C14: =Dimension_Summary!F6 -> 0 | D14: =Dimension_Summary!D6 -> 755 | E14: =IF(Dimension_Summary!F6="","",IF(Dimension_Summary!F6<=Config!B4,Config!B2,IF(Dimension_Summary!F6<=Config!B7,Config!B5,IF(Dimension_Summary!F6<=Config!B10,Config!B8,Config!B11)))) -> Emerging
A15: =Dimension_Summary!A7 -> Technology Infrastructure & Tooling | B15: =Dimension_Summary!E7 -> 0 | C15: =Dimension_Summary!F7 -> 0 | D15: =Dimension_Summary!D7 -> 815 | E15: =IF(Dimension_Summary!F7="","",IF(Dimension_Summary!F7<=Config!B4,Config!B2,IF(Dimension_Summary!F7<=Config!B7,Config!B5,IF(Dimension_Summary!F7<=Config!B10,Config!B8,Config!B11)))) -> Emerging
A16: =Dimension_Summary!A8 -> Use Case Maturity & Adoption | B16: =Dimension_Summary!E8 -> 0 | C16: =Dimension_Summary!F8 -> 0 | D16: =Dimension_Summary!D8 -> 540 | E16: =IF(Dimension_Summary!F8="","",IF(Dimension_Summary!F8<=Config!B4,Config!B2,IF(Dimension_Summary!F8<=Config!B7,Config!B5,IF(Dimension_Summary!F8<=Config!B10,Config!B8,Config!B11)))) -> Emerging
A18: GAP-ANALYSE — AFSTAND TOT STREEFNIVEAU (80%)
A19: Dimensie | B19: Huidige score (%) | C19: Streefwaarde (%) | D19: GAP (%) | E19: Prioriteit
A20: =Dimension_Summary!A2 -> Data Readiness | B20: =Dimension_Summary!F2 -> 0 | C20: 80% | D20: =IF(Dimension_Summary!F2="","",ROUND(80-Dimension_Summary!F2,1)) -> 80 | E20: =IF(Dimension_Summary!F2="","",IF(Dimension_Summary!F2>=80,"✓ Op niveau",IF(Dimension_Summary!F2>=60,"Laag",IF(Dimension_Summary!F2>=40,"Middel","Hoog")))) -> Hoog
A21: =Dimension_Summary!A3 -> Operations, Culture & Delivery | B21: =Dimension_Summary!F3 -> 0 | C21: 80% | D21: =IF(Dimension_Summary!F3="","",ROUND(80-Dimension_Summary!F3,1)) -> 80 | E21: =IF(Dimension_Summary!F3="","",IF(Dimension_Summary!F3>=80,"✓ Op niveau",IF(Dimension_Summary!F3>=60,"Laag",IF(Dimension_Summary!F3>=40,"Middel","Hoog")))) -> Hoog
A22: =Dimension_Summary!A4 -> Risk, Compliance & Responsible AI | B22: =Dimension_Summary!F4 -> 0 | C22: 80% | D22: =IF(Dimension_Summary!F4="","",ROUND(80-Dimension_Summary!F4,1)) -> 80 | E22: =IF(Dimension_Summary!F4="","",IF(Dimension_Summary!F4>=80,"✓ Op niveau",IF(Dimension_Summary!F4>=60,"Laag",IF(Dimension_Summary!F4>=40,"Middel","Hoog")))) -> Hoog
A23: =Dimension_Summary!A5 -> Skills & Organizational Capability | B23: =Dimension_Summary!F5 -> 0 | C23: 80% | D23: =IF(Dimension_Summary!F5="","",ROUND(80-Dimension_Summary!F5,1)) -> 80 | E23: =IF(Dimension_Summary!F5="","",IF(Dimension_Summary!F5>=80,"✓ Op niveau",IF(Dimension_Summary!F5>=60,"Laag",IF(Dimension_Summary!F5>=40,"Middel","Hoog")))) -> Hoog
A24: =Dimension_Summary!A6 -> Strategic & Leadership Readiness | B24: =Dimension_Summary!F6 -> 0 | C24: 80% | D24: =IF(Dimension_Summary!F6="","",ROUND(80-Dimension_Summary!F6,1)) -> 80 | E24: =IF(Dimension_Summary!F6="","",IF(Dimension_Summary!F6>=80,"✓ Op niveau",IF(Dimension_Summary!F6>=60,"Laag",IF(Dimension_Summary!F6>=40,"Middel","Hoog")))) -> Hoog
A25: =Dimension_Summary!A7 -> Technology Infrastructure & Tooling | B25: =Dimension_Summary!F7 -> 0 | C25: 80% | D25: =IF(Dimension_Summary!F7="","",ROUND(80-Dimension_Summary!F7,1)) -> 80 | E25: =IF(Dimension_Summary!F7="","",IF(Dimension_Summary!F7>=80,"✓ Op niveau",IF(Dimension_Summary!F7>=60,"Laag",IF(Dimension_Summary!F7>=40,"Middel","Hoog")))) -> Hoog
A26: =Dimension_Summary!A8 -> Use Case Maturity & Adoption | B26: =Dimension_Summary!F8 -> 0 | C26: 80% | D26: =IF(Dimension_Summary!F8="","",ROUND(80-Dimension_Summary!F8,1)) -> 80 | E26: =IF(Dimension_Summary!F8="","",IF(Dimension_Summary!F8>=80,"✓ Op niveau",IF(Dimension_Summary!F8>=60,"Laag",IF(Dimension_Summary!F8>=40,"Middel","Hoog")))) -> Hoog
A27: COMPLIANCE DEKKINGSGRAAD
A28: Framework | B28: Vragen gedekt | C28: Totaal vragen | D28: Dekking (%) | E28: Gem. score (0–5)
A29: EU AI Act | B29: =COUNTIFS(Sheet!$R$2:$R$266,"YES") -> 122 | C29: =Overall_Summary!B8 -> 265 | D29: =IF(C29=0,"",ROUND(B29/C29*100,1)) -> 46 | E29: =IF(COUNTIFS(Sheet!$R$2:$R$266,"YES",Sheet!$Q$2:$Q$266,"<>")=0,"",ROUND(AVERAGEIFS(Sheet!$Q$2:$Q$266,Sheet!$R$2:$R$266,"YES",Sheet!$Q$2:$Q$266,"<>"),2)) -> #DIV/0!
A30: NIST AI RMF | B30: =COUNTIFS(Sheet!$S$2:$S$266,"YES") -> 201 | C30: =Overall_Summary!B8 -> 265 | D30: =IF(C30=0,"",ROUND(B30/C30*100,1)) -> 75.8 | E30: =IF(COUNTIFS(Sheet!$S$2:$S$266,"YES",Sheet!$Q$2:$Q$266,"<>")=0,"",ROUND(AVERAGEIFS(Sheet!$Q$2:$Q$266,Sheet!$S$2:$S$266,"YES",Sheet!$Q$2:$Q$266,"<>"),2)) -> #DIV/0!
A31: ISO 42001 | B31: =COUNTIFS(Sheet!$T$2:$T$266,"YES") -> 202 | C31: =Overall_Summary!B8 -> 265 | D31: =IF(C31=0,"",ROUND(B31/C31*100,1)) -> 76.2 | E31: =IF(COUNTIFS(Sheet!$T$2:$T$266,"YES",Sheet!$Q$2:$Q$266,"<>")=0,"",ROUND(AVERAGEIFS(Sheet!$Q$2:$Q$266,Sheet!$T$2:$T$266,"YES",Sheet!$Q$2:$Q$266,"<>"),2)) -> #DIV/0!
A32: AI TRiSM | B32: =COUNTIFS(Sheet!$U$2:$U$266,"YES") -> 97 | C32: =Overall_Summary!B8 -> 265 | D32: =IF(C32=0,"",ROUND(B32/C32*100,1)) -> 36.6 | E32: =IF(COUNTIFS(Sheet!$U$2:$U$266,"YES",Sheet!$Q$2:$Q$266,"<>")=0,"",ROUND(AVERAGEIFS(Sheet!$Q$2:$Q$266,Sheet!$U$2:$U$266,"YES",Sheet!$Q$2:$Q$266,"<>"),2)) -> #DIV/0!
A33: Vertrouwelijk — Straightable Innovatie & Strategie — Automatisch berekend op basis van ingevulde antwoorden
